<?xml version="1.0" ?>
<!-- =================================================================================== -->
<!-- |    This document was autogenerated by xacro from manipulator.urdf.xacro         | -->
<!-- |    EDITING THIS FILE BY HAND IS NOT RECOMMENDED                                 | -->
<!-- =================================================================================== -->
<robot name="panda">
  <!-- Empty link to referr everything to -->
  <link name="world"/>
  <!-- Wrong masses to test adaptability of the algorithms, on purpose off by 20% -->
  <!--xacro:property
  name="mass_link0" value="3.66357" />
  <xacro:property name="mass_link1" value="2.04471" />
  <xacro:property name="mass_link2" value="2.56414" />
  <xacro:property name="mass_link3" value="2.48050" />
  <xacro:property name="mass_link4" value="2.02754" />
  <xacro:property name="mass_link5" value="3.09611" />
  <xacro:property name="mass_link6" value="1.66736" />
  <xacro:property name="mass_link7" value="0.75606" />
  <xacro:property name="mass_link8" value="0.1" /-->
  <joint name="robot_to_world" type="fixed">
    <parent link="world"/>
    <child link="panda_link0"/>
    <origin rpy="0.0 0.0 0.0" xyz="0.0 0.0 0.0"/>
    <dynamics damping="1.0"/>
  </joint>
  <link name="panda_link0">
    <visual>
      <geometry>
        <mesh filename="package://arm_description/meshes/visual/link0.dae"/>
      </geometry>
    </visual>
    <collision>
      <geometry>
        <mesh filename="package://arm_description/meshes/collision/link0.stl"/>
      </geometry>
    </collision>
    <inertial>
      <origin rpy="0 0 0" xyz="-0.029190 -0.000879 0.056603"/>
      <mass value="3.06357"/>
      <inertia ixx="0.009" ixy="0.0" ixz="-0.00010" iyy="0.0122" iyz="0.0" izz="0.0122"/>
    </inertial>
  </link>
  <link name="panda_link1">
    <visual>
      <geometry>
        <mesh filename="package://arm_description/meshes/visual/link1.dae"/>
      </geometry>
    </visual>
    <collision>
      <geometry>
        <mesh filename="package://arm_description/meshes/collision/link1.stl"/>
      </geometry>
    </collision>
    <inertial>
      <origin rpy="0 0 0" xyz="0.000011 -0.031266 -0.069373"/>
      <mass value="2.34471"/>
      <inertia ixx="0.01418" ixy="0.0" ixz="0.0" iyy="0.01181" iyz="0.00236" izz="0.005515"/>
    </inertial>
  </link>
  <joint name="panda_joint1" type="revolute">
    <safety_controller k_position="100.0" k_velocity="40.0" soft_lower_limit="-2.8973" soft_upper_limit="2.8973"/>
    <origin rpy="0 0 0" xyz="0 0 0.333"/>
    <parent link="panda_link0"/>
    <child link="panda_link1"/>
    <axis xyz="0 0 1"/>
    <limit effort="87" lower="-3.141592653589793" upper="3.141592653589793" velocity="2.1750"/>
    <!-- <limit effort="87" lower="-2.8973" upper="2.8973" velocity="2.1750" /> -->
    <dynamics damping="1.0"/>
  </joint>
  <link name="panda_link2">
    <visual>
      <geometry>
        <mesh filename="package://arm_description/meshes/visual/link2.dae"/>
      </geometry>
    </visual>
    <collision>
      <geometry>
        <mesh filename="package://arm_description/meshes/collision/link2.stl"/>
      </geometry>
    </collision>
    <inertial>
      <origin rpy="0 0 0" xyz="-0.000013 -0.070322 0.031178"/>
      <mass value="2.36414"/>
      <inertia ixx="0.014" ixy="0.0" ixz="0.0" iyy="0.0055" iyz="-0.0023" izz="0.01259"/>
    </inertial>
  </link>
  <joint name="panda_joint2" type="revolute">
    <safety_controller k_position="100.0" k_velocity="40.0" soft_lower_limit="-1.7628" soft_upper_limit="1.7628"/>
    <origin rpy="-1.5707963267948966 0 0" xyz="0 0 0"/>
    <parent link="panda_link1"/>
    <child link="panda_link2"/>
    <axis xyz="0 0 1"/>
    <limit effort="87" lower="-3.141592653589793" upper="3.141592653589793" velocity="2.1750"/>
    <!-- <limit effort="87" lower="-1.7628" upper="1.7628" velocity="2.1750" /> -->
    <dynamics damping="1.0"/>
  </joint>
  <link name="panda_link3">
    <visual>
      <geometry>
        <mesh filename="package://arm_description/meshes/visual/link3.dae"/>
      </geometry>
    </visual>
    <collision>
      <geometry>
        <mesh filename="package://arm_description/meshes/collision/link3.stl"/>
      </geometry>
    </collision>
    <inertial>
      <origin rpy="0 0 0" xyz="0.044348 0.024928 -0.038130"/>
      <mass value="2.3805"/>
      <inertia ixx="0.00716" ixy="-0.00102" ixz="-0.02040" iyy="0.00920" iyz="-0.00102" izz="0.007159"/>
    </inertial>
  </link>
  <joint name="panda_joint3" type="revolute">
    <safety_controller k_position="100.0" k_velocity="40.0" soft_lower_limit="-2.8973" soft_upper_limit="2.8973"/>
    <origin rpy="1.5707963267948966 0 0" xyz="0 -0.316 0"/>
    <parent link="panda_link2"/>
    <child link="panda_link3"/>
    <axis xyz="0 0 1"/>
    <limit effort="87" lower="-3.141592653589793" upper="3.141592653589793" velocity="2.1750"/>
    <!-- <limit effort="87" lower="-2.8973" upper="2.8973" velocity="2.1750" /> -->
    <dynamics damping="1.0"/>
  </joint>
  <link name="panda_link4">
    <visual>
      <geometry>
        <mesh filename="package://arm_description/meshes/visual/link4.dae"/>
      </geometry>
    </visual>
    <collision>
      <geometry>
        <mesh filename="package://arm_description/meshes/collision/link4.stl"/>
      </geometry>
    </collision>
    <inertial>
      <origin rpy="0 0 0" xyz="-0.038550 0.039526 0.024716"/>
      <mass value="2.42754"/>
      <inertia ixx="0.008164" ixy="0.003061" ixz="0.00102" iyy="0.008165" iyz="0.00102" izz="0.009185"/>
    </inertial>
  </link>
  <joint name="panda_joint4" type="revolute">
    <safety_controller k_position="100.0" k_velocity="40.0" soft_lower_limit="-3.0718" soft_upper_limit="-0.0698"/>
    <origin rpy="1.5707963267948966 0 0" xyz="0.0825 0 0"/>
    <parent link="panda_link3"/>
    <child link="panda_link4"/>
    <axis xyz="0 0 1"/>
    <!-- <limit effort="87" lower="-3.0718" upper="-0.0698" velocity="2.1750" /> -->
    <limit effort="87" lower="-3.141592653589793" upper="3.141592653589793" velocity="2.1750"/>
    <dynamics damping="1.0"/>
  </joint>
  <link name="panda_link5">
    <visual>
      <geometry>
        <mesh filename="package://arm_description/meshes/visual/link5.dae"/>
      </geometry>
    </visual>
    <collision>
      <geometry>
        <mesh filename="package://arm_description/meshes/collision/link5.stl"/>
      </geometry>
    </collision>
    <inertial>
      <origin rpy="0 0 0" xyz="-0.000064 0.038412 -0.109970"/>
      <mass value="3.49611"/>
      <inertia ixx="0.0307" ixy="0.0" ixz="0.0" iyy="0.02761" iyz="-0.0613" izz="0.00818"/>
    </inertial>
  </link>
  <joint name="panda_joint5" type="revolute">
    <safety_controller k_position="100.0" k_velocity="40.0" soft_lower_limit="-2.8973" soft_upper_limit="2.8973"/>
    <origin rpy="-1.5707963267948966 0 0" xyz="-0.0825 0.384 0"/>
    <parent link="panda_link4"/>
    <child link="panda_link5"/>
    <axis xyz="0 0 1"/>
    <!-- <limit effort="12" lower="-2.8973" upper="2.8973" velocity="2.6100" /> -->
    <limit effort="87" lower="-3.141592653589793" upper="3.141592653589793" velocity="2.1750"/>
    <dynamics damping="1.0"/>
  </joint>
  <link name="panda_link6">
    <visual>
      <geometry>
        <mesh filename="package://arm_description/meshes/visual/link6.dae"/>
      </geometry>
    </visual>
    <collision>
      <geometry>
        <mesh filename="package://arm_description/meshes/collision/link6.stl"/>
      </geometry>
    </collision>
    <inertial>
      <origin rpy="0 0 0" xyz="0.051002 0.006933 0.006169"/>
      <mass value="1.46736"/>
      <inertia ixx="0.00205" ixy="0.0" ixz="0.0" iyy="0.004089" iyz="0" izz="0.00490"/>
    </inertial>
  </link>
  <joint name="panda_joint6" type="revolute">
    <safety_controller k_position="100.0" k_velocity="40.0" soft_lower_limit="-0.0175" soft_upper_limit="3.7525"/>
    <origin rpy="1.5707963267948966 0 0" xyz="0 0 0"/>
    <parent link="panda_link5"/>
    <child link="panda_link6"/>
    <axis xyz="0 0 1"/>
    <!-- <limit effort="12" lower="-0.0175" upper="3.7525" velocity="2.6100" /> -->
    <limit effort="87" lower="-3.141592653589793" upper="3.141592653589793" velocity="2.1750"/>
    <dynamics damping="1.0"/>
  </joint>
  <link name="panda_link7">
    <visual>
      <geometry>
        <mesh filename="package://arm_description/meshes/visual/link7.dae"/>
      </geometry>
    </visual>
    <collision>
      <geometry>
        <mesh filename="package://arm_description/meshes/collision/link7.stl"/>
      </geometry>
    </collision>
    <inertial>
      <origin rpy="0 0 0" xyz="0 0 0"/>
      <mass value="0.45606"/>
      <inertia ixx="0.3" ixy="0.0" ixz="0.0" iyy="0.3" iyz="0.0" izz="0.3"/>
    </inertial>
  </link>
  <joint name="panda_joint7" type="revolute">
    <safety_controller k_position="100.0" k_velocity="40.0" soft_lower_limit="-2.8973" soft_upper_limit="2.8973"/>
    <origin rpy="1.5707963267948966 0 0" xyz="0.088 0 0"/>
    <parent link="panda_link6"/>
    <child link="panda_link7"/>
    <axis xyz="0 0 1"/>
    <limit effort="12" lower="-2.8973" upper="2.8973" velocity="2.6100"/>
    <dynamics damping="1.0"/>
  </joint>
  <link name="panda_link8">
    <inertial>
      <origin rpy="0 0 0" xyz="0 0 0"/>
      <mass value="0.001"/>
      <inertia ixx="0.3" ixy="0.0" ixz="0.0" iyy="0.3" iyz="0.0" izz="0.3"/>
    </inertial>
  </link>
  <joint name="panda_joint8" type="fixed">
    <origin rpy="0 0 0" xyz="0 0 0.107"/>
    <parent link="panda_link7"/>
    <child link="panda_link8"/>
    <!-- <axis xyz="0 0 1" />
      <limit effort="1" lower="0" upper="0.1" velocity="0.1" />
      <dynamics damping="100" /> -->
  </joint>
  <joint name="panda_hand_joint" type="fixed">
    <parent link="panda_link8"/>
    <child link="panda_hand"/>
    <origin rpy="0 0 -0.7853981633974483" xyz="0 0 0"/>
  </joint>
  <link name="panda_hand">
    <visual>
      <geometry>
        <mesh filename="package://arm_description/meshes/visual/hand.dae"/>
      </geometry>
    </visual>
    <collision>
      <geometry>
        <mesh filename="package://arm_description/meshes/collision/hand.stl"/>
      </geometry>
    </collision>
    <inertial>
      <origin rpy="0 0 0" xyz="0 0 0"/>
      <mass value="0.68"/>
      <inertia ixx="0.1" ixy="0.0" ixz="0.0" iyy="0.1" iyz="0.0" izz="0.1"/>
    </inertial>
  </link>
  <link name="panda_finger">
    <visual name="back">
      <origin rpy="0 0 0" xyz="-0.02 0 0.02"/>
      <geometry>
        <box size="0.01 0.04 0.04"/>
      </geometry>
    </visual>
    <visual name="left">
      <origin rpy="0 0 0" xyz="0 -0.02 0.02"/>
      <geometry>
        <box size="0.04 0.01 0.04"/>
      </geometry>
    </visual>
    <visual name="right">
      <origin rpy="0 0 0" xyz="0 0.02 0.02"/>
      <geometry>
        <box size="0.04 0.01 0.04"/>
      </geometry>
    </visual>
    <visual name="front">
      <origin rpy="0 0 0" xyz="0.02 0 0.02"/>
      <geometry>
        <box size="0.01 0.04 0.04"/>
      </geometry>
    </visual>
    <collision name="back">
      <origin rpy="0 0 0" xyz="-0.02 0 0.02"/>
      <geometry>
        <box size="0.01 0.04 0.04"/>
      </geometry>
    </collision>
    <collision name="left">
      <origin rpy="0 0 0" xyz="0 -0.02 0.02"/>
      <geometry>
        <box size="0.04 0.01 0.04"/>
      </geometry>
    </collision>
    <collision name="right">
      <origin rpy="0 0 0" xyz="0 0.02 0.02"/>
      <geometry>
        <box size="0.04 0.01 0.04"/>
      </geometry>
    </collision>
    <collision name="front">
      <origin rpy="0 0 0" xyz="0.02 0 0.02"/>
      <geometry>
        <box size="0.01 0.04 0.04"/>
      </geometry>
    </collision>
    <inertial>
      <origin rpy="0 0 0" xyz="0 0 0"/>
      <mass value="0.02"/>
      <inertia ixx="0.000001667" ixy="0.0" ixz="0.0" iyy="0.000001667" iyz="0.0" izz="0.000000667"/>
    </inertial>
  </link>
  <joint name="panda_finger_joint" type="fixed">
    <parent link="panda_hand"/>
    <child link="panda_finger"/>
    <origin rpy="0 0 0" xyz="0 0 0.0584"/>
  </joint>
</robot>
